Traceback (most recent call last):
  File "C:\Users\a3nf\Anaconda3\envs\books\lib\site-packages\jupyter_cache\executors\utils.py", line 58, in single_nb_execution
    executenb(
  File "C:\Users\a3nf\Anaconda3\envs\books\lib\site-packages\nbclient\client.py", line 1204, in execute
    return NotebookClient(nb=nb, resources=resources, km=km, **kwargs).execute()
  File "C:\Users\a3nf\Anaconda3\envs\books\lib\site-packages\nbclient\util.py", line 84, in wrapped
    return just_run(coro(*args, **kwargs))
  File "C:\Users\a3nf\Anaconda3\envs\books\lib\site-packages\nbclient\util.py", line 62, in just_run
    return loop.run_until_complete(coro)
  File "C:\Users\a3nf\Anaconda3\envs\books\lib\asyncio\base_events.py", line 647, in run_until_complete
    return future.result()
  File "C:\Users\a3nf\Anaconda3\envs\books\lib\site-packages\nbclient\client.py", line 663, in async_execute
    await self.async_execute_cell(
  File "C:\Users\a3nf\Anaconda3\envs\books\lib\site-packages\nbclient\client.py", line 965, in async_execute_cell
    await self._check_raise_for_error(cell, cell_index, exec_reply)
  File "C:\Users\a3nf\Anaconda3\envs\books\lib\site-packages\nbclient\client.py", line 862, in _check_raise_for_error
    raise CellExecutionError.from_cell_and_msg(cell, exec_reply_content)
nbclient.exceptions.CellExecutionError: An error occurred while executing the following cell:
------------------
from pathlib import Path
blocks = Path('c_hominis.fasta').read_text().split('>')

dictseqs = {}

for b in blocks:
    if b != '':
        lines = b.splitlines()
        header = lines[0]
        seq = ''.join(lines[1:])
        # retirar o Uniprot Id do header
        parts = header.split('|')
        # separando por | um header, o ac estÃ¡ na posiÃ§Ã£o 1
        ac = parts[1]

        # finalmente, por o resultado no dicionÃ¡rio
        dictseqs[ac] = seq


# Ver algumas proteÃ­nas...
for ac in ['A7HZY9','A7I3U6','A7I3S8']:
    print(f'{ac}: {seqs[ac]}\n')
------------------

[1;31m---------------------------------------------------------------------------[0m
[1;31mTypeError[0m                                 Traceback (most recent call last)
Cell [1;32mIn[34], line 22[0m
[0;32m     20[0m [38;5;66;03m# Ver algumas proteÃ­nas...[39;00m
[0;32m     21[0m [38;5;28;01mfor[39;00m ac [38;5;129;01min[39;00m [[38;5;124m'[39m[38;5;124mA7HZY9[39m[38;5;124m'[39m,[38;5;124m'[39m[38;5;124mA7I3U6[39m[38;5;124m'[39m,[38;5;124m'[39m[38;5;124mA7I3S8[39m[38;5;124m'[39m]:
[1;32m---> 22[0m     [38;5;28mprint[39m([38;5;124mf[39m[38;5;124m'[39m[38;5;132;01m{[39;00mac[38;5;132;01m}[39;00m[38;5;124m: [39m[38;5;132;01m{[39;00mseqs[ac][38;5;132;01m}[39;00m[38;5;130;01m\n[39;00m[38;5;124m'[39m)

[1;31mTypeError[0m: list indices must be integers or slices, not str
TypeError: list indices must be integers or slices, not str

